Workbook

Sheet General
A1: Source: Basílio et al.,(2022). A systematic review of the applications of multi-criteria decision aid methods
A2: A Method | B2: B Publication Time | C2: C Recorded Count (all fields) | D2: D Research Areas In Which The Method Has Been Mainly Used | E2: E Recorded Count (in specific field indicated in previous column) | F2: Publication Time (Integrated/Hybrid Model) | G2: Hybrid Model | H2: New Technologies (Machine Learning) | I2: F Research Area In which this work focuses | J2: G Recorded Count In Software Engineering | K2: H Recorded Count Software Engineering | S2: Method | T2: Publication Time | U2: Total Recorded Count in Software Engineering | V2: Recorded Count Software Engineering on each Database
K3: IEEE Xplore | L3: Scopus | M3: Springer | N3: WoS
A4: AHP | B4: 1990-2021 | C4: 6835 | D4: Engineering | E4: 2329 | F4: 1995-2021 | G4: 1388 | H4: 38 | I4: Software engineering | J4: =K4+L4+M4+N4 -> 237 | K4: 23 | L4: 41 | M4: 128 | N4: 45 | V4: IEEE Xplore | W4: Scopus | X4: Springer | Y4: WoS
A5: TOPSIS | B5: 1991-2021 | C5: 4907 | D5: Computer science | E5: 1797 | F5: 2003-2021 | G5: 1024 | H5: 47 | I5: Software engineering | J5: =K5+L5+M5+N5 -> 84 | K5: 16 | L5: 15 | M5: 20 | N5: 33 | S5: AHP | T5: 1990-2023 | U5: 237 | V5: 23 | W5: 41 | X5: 128 | Y5: 45
A6: VIKOR | B6: 2002–2021 | C6: 1475 | D6: Computer science | E6: 519 | F6: 2009-2021 | G6: 416 | H6: 5 | I6: Software engineering | J6: =K6+L6+M6+N6 -> 11 | K6: 0 | L6: 2 | M6: 9 | N6: 0 | S6: TOPSIS | T6: 1991-2023 | U6: 84 | V6: 16 | W6: 15 | X6: 20 | Y6: 33
A7: PROMETHEE | B7: 1989–2021 | C7: 1382 | D7: Engineering | E7: 445 | F7: 2001-2021 | G7: 202 | H7: 16 | I7: Software engineering | J7: =K7+L7+M7+N7 -> 21 | K7: 3 | L7: 4 | M7: 10 | N7: 4 | S7: ELECTRE | T7: 1991–2023 | U7: 23 | V7: 5 | W7: 6 | X7: 6 | Y7: 6
A8: ANP | B8: 2000–2021 | C8: 1262 | D8: Engineering | E8: 428 | F8: 2006–2021 | G8: 488 | H8: 10 | I8: Software engineering | J8: =K8+L8+M8+N8 -> 19 | K8: 1 | L8: 3 | M8: 9 | N8: 6 | S8: PROMETHEE | T8: 1989–2023 | U8: 21 | V8: 3 | W8: 4 | X8: 10 | Y8: 4
A9: ELECTRE | B9: 1991–2021 | C9: 1005 | D9: Computer science | E9: 331 | F9: 2003-2021 | G9: 120 | H9: 6 | I9: Software engineering | J9: =K9+L9+M9+N9 -> 23 | K9: 5 | L9: 6 | M9: 6 | N9: 6 | S9: ANP | T9: 2000–2023 | U9: 19 | V9: 1 | W9: 3 | X9: 9 | Y9: 6
A10: DEMATEL | B10: 2007–2021 | C10: 888 | D10: Computer science | E10: 289 | F10: 2007-2021 | G10: 476 | H10: 5 | I10: Software engineering | J10: =K10+L10+M10+N10 -> 15 | K10: 0 | L10: 2 | M10: 8 | N10: 5 | S10: DEMATEL | T10: 2007–2023 | U10: 15 | V10: 0 | W10: 2 | X10: 8 | Y10: 5
A11: TODIM | B11: 1999–2021 | C11: 306 | D11: Computer science | E11: 171 | F11: 2013-2021 | G11: 56 | H11: 2 | I11: Software engineering | J11: =K11+L11+M11+N11 -> 4 | K11: 1 | L11: 0 | M11: 0 | N11: 3 | S11: VIKOR | T11: 2002–2023 | U11: 11 | V11: 0 | W11: 2 | X11: 9 | Y11: 0
A12: MULTIMOORA | B12: 2011–2021 | C12: 198 | D12: Computer science | E12: 75 | F12: 2011-2021 | G12: 43 | H12: 0 | I12: Software engineering | J12: =K12+L12+M12+N12 -> 0 | K12: 0 | L12: 0 | M12: 0 | N12: 0 | S12: MACBETH | T12: 1999–2023 | U12: 10 | V12: 1 | W12: 2 | X12: 5 | Y12: 2
A13: MACBETH | B13: 1999–2021 | C13: 162 | D13: Computer science | E13: 47 | F13: 1999-2021 | G13: 27 | H13: 0 | I13: Software engineering | J13: =K13+L13+M13+N13 -> 10 | K13: 1 | L13: 2 | M13: 5 | N13: 2 | S13: CBR | T13: 1996–2023 | U13: 4 | V13: 1 | W13: 0 | X13: 2 | Y13: 1
A14: DRSA | B14: 2002–2021 | C14: 85 | D14: Computer science | E14: 51 | F14: 2012-2021 | G14: 20 | H14: 4 | I14: Software engineering | J14: =K14+L14+M14+N14 -> 1 | K14: 1 | L14: 0 | M14: 0 | N14: 0 | S14: TODIM | T14: 1999–2023 | U14: 4 | V14: 1 | W14: 0 | X14: 0 | Y14: 3
A15: WPM | B15: 1997–2021 | C15: 57 | D15: Computer science | E15: 23 | F15: 2014-2021 | G15: 7 | H15: 0 | I15: Software engineering | J15: =K15+L15+M15+N15 -> 4 | K15: 0 | L15: 0 | M15: 4 | N15: 0 | S15: WPM | T15: 1997–2023 | U15: 4 | V15: 0 | W15: 0 | X15: 4 | Y15: 0
A16: CBR | B16: 1996–2021 | C16: 40 | D16: Computer science | E16: 25 | F16: 2006-2020 | G16: 10 | H16: 1 | I16: Software engineering | J16: =K16+L16+M16+N16 -> 4 | K16: 1 | L16: 0 | M16: 2 | N16: 1 | S16: DRSA | T16: 2002–2023 | U16: 1 | V16: 1 | W16: 0 | X16: 0 | Y16: 0
... A18: PAPRIKA | B18: 2014–2021 | C18: 12 | D18: Computer science | E18: 4 | F18: 2020 | G18: 1 | H18: 0 | I18: Software engineering | J18: =K18+L18+M18+N18 -> 0 | K18: 0 | L18: 0 | M18: 0 | N18: 0 | S18: MULTIMOORA | T18: 2011–2023 | U18: 0 | V18: 0 | W18: 0 | X18: 0 | Y18: 0
I19: Total | J19: =SUM(J4:J18) -> 433 | S19: PAPRIKA | T19: 2014–2023 | U19: 0 | V19: 0 | W19: 0 | X19: 0 | Y19: 0
S20: TOTAL | U20: 433 | V20: 52 | W20: 77 | X20: 201 | Y20: 105
A24: Method | B24: Search Criteria to reach the recorded count on Software Engineering
A25: AHP | B25: (("multi-attribute decision making" OR "madm" OR "mcda" OR "modm" OR "mcdm" OR "multi-criteria" OR "multi-criteria" OR "multiplecriteria") AND ("software engineer*") AND("ahp" OR {analytic hierarchy process}))
A26: TOPSIS | B26: (("multi-attribute decision making" OR "madm" OR "mcda" OR "modm" OR "mcdm" OR "multi-criteria" OR "multi-criteria" OR "multiplecriteria") AND ("software engineer*") AND("topsis"))
A27: VIKOR | B27: (("multi-attribute decision making" OR "madm" OR "mcda" OR "modm" OR "mcdm" OR "multi-criteria" OR "multi-criteria" OR "multiplecriteria") AND ("software engineer*") AND("vikor"))
A28: PROMETHEE | B28: (("multi-attribute decision making" OR "madm" OR "mcda" OR "modm" OR "mcdm" OR "multi-criteria" OR "multi-criteria" OR "multiplecriteria") AND ("software engineer*") AND("promethee"))
A29: ANP | B29: (("multi-attribute decision making" OR "madm" OR "mcda" OR "modm" OR "mcdm" OR "multi-criteria" OR "multi-criteria" OR "multiplecriteria") AND ("software engineer*") AND("anp"))
A30: ELECTRE | B30: (("multi-attribute decision making" OR "madm" OR "mcda" OR "modm" OR "mcdm" OR "multi-criteria" OR "multi-criteria" OR "multiplecriteria") AND ("software engineer*") AND("electre"))
A31: DEMATEL | B31: (("multi-attribute decision making" OR "madm" OR "mcda" OR "modm" OR "mcdm" OR "multi-criteria" OR "multi-criteria" OR "multiplecriteria") AND ("software engineer*") AND("dematel"))
A32: TODIM | B32: (("multi-attribute decision making" OR "madm" OR "mcda" OR "modm" OR "mcdm" OR "multi-criteria" OR "multi-criteria" OR "multiplecriteria") AND ("software engineer*") AND("todim"))
A33: MULTIMOORA | B33: (("multi-attribute decision making" OR "madm" OR "mcda" OR "modm" OR "mcdm" OR "multi-criteria" OR "multi-criteria" OR "multiplecriteria") AND ("software engineer*") AND("multimoora"))
A34: MACBETH | B34: (("multi-attribute decision making" OR "madm" OR "mcda" OR "modm" OR "mcdm" OR "multi-criteria" OR "multi-criteria" OR "multiplecriteria") AND ("software engineer*") AND("macbeth"))
A35: DRSA | B35: (("multi-attribute decision making" OR "madm" OR "mcda" OR "modm" OR "mcdm" OR "multi-criteria" OR "multi-criteria" OR "multiplecriteria") AND ("software engineer*") AND("drsa"))
... A39: PAPRIKA | B39: (("multi-attribute decision making" OR "madm" OR "mcda" OR "modm" OR "mcdm" OR "multi-criteria" OR "multi-criteria" OR "multiplecriteria") AND ("software engineer*") AND("paprika"))

Sheet Areas
A1: Recorded count for each SWEBOK guide V4 knowledge area | B1: AHP | C1: TOPSIS | D1: VIKOR | E1: PROMETHEE | F1: ANP | G1: ELECTRE | H1: DEMATEL | I1: TODIM | J1: MULTIMOORA | K1: MACBETH | L1: DRSA | M1: WPM | N1: CBR | O1: FITRADEOFF | P1: PAPRIKA | R1: Sub-Total
A2: Software Requirements | B2: =SUMIFS('Counting Class'!T:T,'Counting Class'!B:B,"=1",'Counting Class'!T:T,"=1") -> 33 | C2: =SUMIFS('Counting Class'!U:U,'Counting Class'!B:B,"=1",'Counting Class'!U:U,"=1") -> 10 | D2: =SUMIFS('Counting Class'!V:V,'Counting Class'!B:B,"=1",'Counting Class'!V:V,"=1") -> 1 | E2: =SUMIFS('Counting Class'!W:W,'Counting Class'!C:C,"=1",'Counting Class'!W:W,"=1") -> 2 | F2: =SUMIFS('Counting Class'!X:X,'Counting Class'!D:D,"=1",'Counting Class'!X:X,"=1") -> 2 | G2: =SUMIFS('Counting Class'!Y:Y,'Counting Class'!E:E,"=1",'Counting Class'!Y:Y,"=1") -> 1 | H2: =SUMIFS('Counting Class'!Z:Z,'Counting Class'!F:F,"=1",'Counting Class'!Z:Z,"=1") -> 1 | I2: =SUMIFS('Counting Class'!AA:AA,'Counting Class'!G:G,"=1",'Counting Class'!AA:AA,"=1") -> 0 | J2: =SUMIFS('Counting Class'!AB:AB,'Counting Class'!H:H,"=1",'Counting Class'!AB:AB,"=1") -> 0 | K2: =SUMIFS('Counting Class'!AC:AC,'Counting Class'!I:I,"=1",'Counting Class'!AC:AC,"=1") -> 0 | L2: =SUMIFS('Counting Class'!AD:AD,'Counting Class'!J:J,"=1",'Counting Class'!AD:AD,"=1") -> 0 | M2: =SUMIFS('Counting Class'!AE:AE,'Counting Class'!K:K,"=1",'Counting Class'!AE:AE,"=1") -> 0 | N2: =SUMIFS('Counting Class'!AF:AF,'Counting Class'!L:L,"=1",'Counting Class'!AF:AF,"=1") -> 0 | O2: =SUMIFS('Counting Class'!AG:AG,'Counting Class'!M:M,"=1",'Counting Class'!AG:AG,"=1") -> 0 | P2: =SUMIFS('Counting Class'!AH:AH,'Counting Class'!N:N,"=1",'Counting Class'!AH:AH,"=1") -> 0 | R2: =SUM(Areas!$B2:$P2) -> 50
A3: Software Architecture | B3: =SUMIFS('Counting Class'!T:T,'Counting Class'!C:C,"=1",'Counting Class'!T:T,"=1") -> 36 | C3: =SUMIFS('Counting Class'!U:U,'Counting Class'!C:C,"=1",'Counting Class'!U:U,"=1") -> 14 | D3: =SUMIFS('Counting Class'!V:V,'Counting Class'!C:C,"=1",'Counting Class'!V:V,"=1") -> 4 | E3: =SUMIFS('Counting Class'!W:W,'Counting Class'!D:D,"=1",'Counting Class'!W:W,"=1") -> 0 | F3: =SUMIFS('Counting Class'!X:X,'Counting Class'!E:E,"=1",'Counting Class'!X:X,"=1") -> 1 | G3: =SUMIFS('Counting Class'!Y:Y,'Counting Class'!F:F,"=1",'Counting Class'!Y:Y,"=1") -> 2 | H3: =SUMIFS('Counting Class'!Z:Z,'Counting Class'!G:G,"=1",'Counting Class'!Z:Z,"=1") -> 0 | I3: =SUMIFS('Counting Class'!AA:AA,'Counting Class'!H:H,"=1",'Counting Class'!AA:AA,"=1") -> 0 | J3: =SUMIFS('Counting Class'!AB:AB,'Counting Class'!I:I,"=1",'Counting Class'!AB:AB,"=1") -> 0 | K3: =SUMIFS('Counting Class'!AC:AC,'Counting Class'!J:J,"=1",'Counting Class'!AC:AC,"=1") -> 2 | L3: =SUMIFS('Counting Class'!AD:AD,'Counting Class'!K:K,"=1",'Counting Class'!AD:AD,"=1") -> 0 | M3: =SUMIFS('Counting Class'!AE:AE,'Counting Class'!L:L,"=1",'Counting Class'!AE:AE,"=1") -> 0 | N3: =SUMIFS('Counting Class'!AF:AF,'Counting Class'!M:M,"=1",'Counting Class'!AF:AF,"=1") -> 1 | O3: =SUMIFS('Counting Class'!AG:AG,'Counting Class'!N:N,"=1",'Counting Class'!AG:AG,"=1") -> 0 | P3: =SUMIFS('Counting Class'!AH:AH,'Counting Class'!O:O,"=1",'Counting Class'!AH:AH,"=1") -> 0 | R3: =SUM(Areas!$B3:$P3) -> 60
A4: Software Design | B4: =SUMIFS('Counting Class'!T:T,'Counting Class'!D:D,"=1",'Counting Class'!T:T,"=1") -> 10 | C4: =SUMIFS('Counting Class'!U:U,'Counting Class'!D:D,"=1",'Counting Class'!U:U,"=1") -> 2 | D4: =SUMIFS('Counting Class'!V:V,'Counting Class'!D:D,"=1",'Counting Class'!V:V,"=1") -> 0 | E4: =SUMIFS('Counting Class'!W:W,'Counting Class'!E:E,"=1",'Counting Class'!W:W,"=1") -> 0 | F4: =SUMIFS('Counting Class'!X:X,'Counting Class'!F:F,"=1",'Counting Class'!X:X,"=1") -> 2 | G4: =SUMIFS('Counting Class'!Y:Y,'Counting Class'!G:G,"=1",'Counting Class'!Y:Y,"=1") -> 0 | H4: =SUMIFS('Counting Class'!Z:Z,'Counting Class'!H:H,"=1",'Counting Class'!Z:Z,"=1") -> 0 | I4: =SUMIFS('Counting Class'!AA:AA,'Counting Class'!I:I,"=1",'Counting Class'!AA:AA,"=1") -> 0 | J4: =SUMIFS('Counting Class'!AB:AB,'Counting Class'!J:J,"=1",'Counting Class'!AB:AB,"=1") -> 0 | K4: =SUMIFS('Counting Class'!AC:AC,'Counting Class'!K:K,"=1",'Counting Class'!AC:AC,"=1") -> 5 | L4: =SUMIFS('Counting Class'!AD:AD,'Counting Class'!L:L,"=1",'Counting Class'!AD:AD,"=1") -> 0 | M4: =SUMIFS('Counting Class'!AE:AE,'Counting Class'!M:M,"=1",'Counting Class'!AE:AE,"=1") -> 2 | N4: =SUMIFS('Counting Class'!AF:AF,'Counting Class'!N:N,"=1",'Counting Class'!AF:AF,"=1") -> 0 | O4: =SUMIFS('Counting Class'!AG:AG,'Counting Class'!O:O,"=1",'Counting Class'!AG:AG,"=1") -> 0 | P4: =SUMIFS('Counting Class'!AH:AH,'Counting Class'!P:P,"=1",'Counting Class'!AH:AH,"=1") -> 0 | R4: =SUM(Areas!$B4:$P4) -> 21
A5: Software Construction | B5: =SUMIFS('Counting Class'!T:T,'Counting Class'!E:E,"=1",'Counting Class'!T:T,"=1") -> 11 | C5: =SUMIFS('Counting Class'!U:U,'Counting Class'!E:E,"=1",'Counting Class'!U:U,"=1") -> 2 | D5: =SUMIFS('Counting Class'!V:V,'Counting Class'!E:E,"=1",'Counting Class'!V:V,"=1") -> 0 | E5: =SUMIFS('Counting Class'!W:W,'Counting Class'!F:F,"=1",'Counting Class'!W:W,"=1") -> 0 | F5: =SUMIFS('Counting Class'!X:X,'Counting Class'!G:G,"=1",'Counting Class'!X:X,"=1") -> 0 | G5: =SUMIFS('Counting Class'!Y:Y,'Counting Class'!H:H,"=1",'Counting Class'!Y:Y,"=1") -> 0 | H5: =SUMIFS('Counting Class'!Z:Z,'Counting Class'!I:I,"=1",'Counting Class'!Z:Z,"=1") -> 0 | I5: =SUMIFS('Counting Class'!AA:AA,'Counting Class'!J:J,"=1",'Counting Class'!AA:AA,"=1") -> 1 | J5: =SUMIFS('Counting Class'!AB:AB,'Counting Class'!K:K,"=1",'Counting Class'!AB:AB,"=1") -> 0 | K5: =SUMIFS('Counting Class'!AC:AC,'Counting Class'!L:L,"=1",'Counting Class'!AC:AC,"=1") -> 2 | L5: =SUMIFS('Counting Class'!AD:AD,'Counting Class'!M:M,"=1",'Counting Class'!AD:AD,"=1") -> 0 | M5: =SUMIFS('Counting Class'!AE:AE,'Counting Class'!N:N,"=1",'Counting Class'!AE:AE,"=1") -> 0 | N5: =SUMIFS('Counting Class'!AF:AF,'Counting Class'!O:O,"=1",'Counting Class'!AF:AF,"=1") -> 0 | O5: =SUMIFS('Counting Class'!AG:AG,'Counting Class'!P:P,"=1",'Counting Class'!AG:AG,"=1") -> 0 | P5: =SUMIFS('Counting Class'!AH:AH,'Counting Class'!Q:Q,"=1",'Counting Class'!AH:AH,"=1") -> 0 | R5: =SUM(Areas!$B5:$P5) -> 16
A6: Software Testing | B6: =SUMIFS('Counting Class'!T:T,'Counting Class'!F:F,"=1",'Counting Class'!T:T,"=1") -> 18 | C6: =SUMIFS('Counting Class'!U:U,'Counting Class'!F:F,"=1",'Counting Class'!U:U,"=1") -> 8 | D6: =SUMIFS('Counting Class'!V:V,'Counting Class'!F:F,"=1",'Counting Class'!V:V,"=1") -> 1 | E6: =SUMIFS('Counting Class'!W:W,'Counting Class'!G:G,"=1",'Counting Class'!W:W,"=1") -> 0 | F6: =SUMIFS('Counting Class'!X:X,'Counting Class'!H:H,"=1",'Counting Class'!X:X,"=1") -> 1 | G6: =SUMIFS('Counting Class'!Y:Y,'Counting Class'!I:I,"=1",'Counting Class'!Y:Y,"=1") -> 0 | H6: =SUMIFS('Counting Class'!Z:Z,'Counting Class'!J:J,"=1",'Counting Class'!Z:Z,"=1") -> 2 | I6: =SUMIFS('Counting Class'!AA:AA,'Counting Class'!K:K,"=1",'Counting Class'!AA:AA,"=1") -> 0 | J6: =SUMIFS('Counting Class'!AB:AB,'Counting Class'!L:L,"=1",'Counting Class'!AB:AB,"=1") -> 0 | K6: =SUMIFS('Counting Class'!AC:AC,'Counting Class'!M:M,"=1",'Counting Class'!AC:AC,"=1") -> 3 | L6: =SUMIFS('Counting Class'!AD:AD,'Counting Class'!N:N,"=1",'Counting Class'!AD:AD,"=1") -> 0 | M6: =SUMIFS('Counting Class'!AE:AE,'Counting Class'!O:O,"=1",'Counting Class'!AE:AE,"=1") -> 0 | N6: =SUMIFS('Counting Class'!AF:AF,'Counting Class'!P:P,"=1",'Counting Class'!AF:AF,"=1") -> 0 | O6: =SUMIFS('Counting Class'!AG:AG,'Counting Class'!Q:Q,"=1",'Counting Class'!AG:AG,"=1") -> 0 | P6: =SUMIFS('Counting Class'!AH:AH,'Counting Class'!R:R,"=1",'Counting Class'!AH:AH,"=1") -> 0 | R6: =SUM(Areas!$B6:$P6) -> 33
A7: Software Engineering Operations | B7: =SUMIFS('Counting Class'!T:T,'Counting Class'!G:G,"=1",'Counting Class'!T:T,"=1") -> 2 | C7: =SUMIFS('Counting Class'!U:U,'Counting Class'!G:G,"=1",'Counting Class'!U:U,"=1") -> 0 | D7: =SUMIFS('Counting Class'!V:V,'Counting Class'!G:G,"=1",'Counting Class'!V:V,"=1") -> 0 | E7: =SUMIFS('Counting Class'!W:W,'Counting Class'!H:H,"=1",'Counting Class'!W:W,"=1") -> 0 | F7: =SUMIFS('Counting Class'!X:X,'Counting Class'!I:I,"=1",'Counting Class'!X:X,"=1") -> 2 | G7: =SUMIFS('Counting Class'!Y:Y,'Counting Class'!J:J,"=1",'Counting Class'!Y:Y,"=1") -> 2 | H7: =SUMIFS('Counting Class'!Z:Z,'Counting Class'!K:K,"=1",'Counting Class'!Z:Z,"=1") -> 1 | I7: =SUMIFS('Counting Class'!AA:AA,'Counting Class'!L:L,"=1",'Counting Class'!AA:AA,"=1") -> 1 | J7: =SUMIFS('Counting Class'!AB:AB,'Counting Class'!M:M,"=1",'Counting Class'!AB:AB,"=1") -> 0 | K7: =SUMIFS('Counting Class'!AC:AC,'Counting Class'!N:N,"=1",'Counting Class'!AC:AC,"=1") -> 0 | L7: =SUMIFS('Counting Class'!AD:AD,'Counting Class'!O:O,"=1",'Counting Class'!AD:AD,"=1") -> 0 | M7: =SUMIFS('Counting Class'!AE:AE,'Counting Class'!P:P,"=1",'Counting Class'!AE:AE,"=1") -> 0 | N7: =SUMIFS('Counting Class'!AF:AF,'Counting Class'!Q:Q,"=1",'Counting Class'!AF:AF,"=1") -> 0 | O7: =SUMIFS('Counting Class'!AG:AG,'Counting Class'!R:R,"=1",'Counting Class'!AG:AG,"=1") -> 0 | P7: =SUMIFS('Counting Class'!AH:AH,'Counting Class'!S:S,"=1",'Counting Class'!AH:AH,"=1") -> 0 | R7: =SUM(Areas!$B7:$P7) -> 8
A8: Software Maintenance | B8: =SUMIFS('Counting Class'!T:T,'Counting Class'!H:H,"=1",'Counting Class'!T:T,"=1") -> 2 | C8: =SUMIFS('Counting Class'!U:U,'Counting Class'!H:H,"=1",'Counting Class'!U:U,"=1") -> 2 | D8: =SUMIFS('Counting Class'!V:V,'Counting Class'!H:H,"=1",'Counting Class'!V:V,"=1") -> 0 | E8: =SUMIFS('Counting Class'!W:W,'Counting Class'!I:I,"=1",'Counting Class'!W:W,"=1") -> 0 | F8: =SUMIFS('Counting Class'!X:X,'Counting Class'!J:J,"=1",'Counting Class'!X:X,"=1") -> 1 | G8: =SUMIFS('Counting Class'!Y:Y,'Counting Class'!K:K,"=1",'Counting Class'!Y:Y,"=1") -> 4 | H8: =SUMIFS('Counting Class'!Z:Z,'Counting Class'!L:L,"=1",'Counting Class'!Z:Z,"=1") -> 1 | I8: =SUMIFS('Counting Class'!AA:AA,'Counting Class'!M:M,"=1",'Counting Class'!AA:AA,"=1") -> 2 | J8: =SUMIFS('Counting Class'!AB:AB,'Counting Class'!N:N,"=1",'Counting Class'!AB:AB,"=1") -> 0 | K8: =SUMIFS('Counting Class'!AC:AC,'Counting Class'!O:O,"=1",'Counting Class'!AC:AC,"=1") -> 0 | L8: =SUMIFS('Counting Class'!AD:AD,'Counting Class'!P:P,"=1",'Counting Class'!AD:AD,"=1") -> 0 | M8: =SUMIFS('Counting Class'!AE:AE,'Counting Class'!Q:Q,"=1",'Counting Class'!AE:AE,"=1") -> 0 | N8: =SUMIFS('Counting Class'!AF:AF,'Counting Class'!R:R,"=1",'Counting Class'!AF:AF,"=1") -> 0 | O8: =SUMIFS('Counting Class'!AG:AG,'Counting Class'!S:S,"=1",'Counting Class'!AG:AG,"=1") -> 0 | P8: =SUMIFS('Counting Class'!AH:AH,'Counting Class'!T:T,"=1",'Counting Class'!AH:AH,"=1") -> 0 | R8: =SUM(Areas!$B8:$P8) -> 12
A9: Software Configuration Management | B9: =SUMIFS('Counting Class'!T:T,'Counting Class'!I:I,"=1",'Counting Class'!T:T,"=1") -> 6 | C9: =SUMIFS('Counting Class'!U:U,'Counting Class'!I:I,"=1",'Counting Class'!U:U,"=1") -> 2 | D9: =SUMIFS('Counting Class'!V:V,'Counting Class'!I:I,"=1",'Counting Class'!V:V,"=1") -> 0 | E9: =SUMIFS('Counting Class'!W:W,'Counting Class'!J:J,"=1",'Counting Class'!W:W,"=1") -> 1 | F9: =SUMIFS('Counting Class'!X:X,'Counting Class'!K:K,"=1",'Counting Class'!X:X,"=1") -> 3 | G9: =SUMIFS('Counting Class'!Y:Y,'Counting Class'!L:L,"=1",'Counting Class'!Y:Y,"=1") -> 1 | H9: =SUMIFS('Counting Class'!Z:Z,'Counting Class'!M:M,"=1",'Counting Class'!Z:Z,"=1") -> 8 | I9: =SUMIFS('Counting Class'!AA:AA,'Counting Class'!N:N,"=1",'Counting Class'!AA:AA,"=1") -> 1 | J9: =SUMIFS('Counting Class'!AB:AB,'Counting Class'!O:O,"=1",'Counting Class'!AB:AB,"=1") -> 0 | K9: =SUMIFS('Counting Class'!AC:AC,'Counting Class'!P:P,"=1",'Counting Class'!AC:AC,"=1") -> 1 | L9: =SUMIFS('Counting Class'!AD:AD,'Counting Class'!Q:Q,"=1",'Counting Class'!AD:AD,"=1") -> 1 | M9: =SUMIFS('Counting Class'!AE:AE,'Counting Class'!R:R,"=1",'Counting Class'!AE:AE,"=1") -> 0 | N9: =SUMIFS('Counting Class'!AF:AF,'Counting Class'!S:S,"=1",'Counting Class'!AF:AF,"=1") -> 0 | O9: =SUMIFS('Counting Class'!AG:AG,'Counting Class'!T:T,"=1",'Counting Class'!AG:AG,"=1") -> 0 | P9: =SUMIFS('Counting Class'!AH:AH,'Counting Class'!U:U,"=1",'Counting Class'!AH:AH,"=1") -> 0 | R9: =SUM(Areas!$B9:$P9) -> 24
A10: Software Engineering Management | B10: =SUMIFS('Counting Class'!T:T,'Counting Class'!J:J,"=1",'Counting Class'!T:T,"=1") -> 20 | C10: =SUMIFS('Counting Class'!U:U,'Counting Class'!J:J,"=1",'Counting Class'!U:U,"=1") -> 7 | D10: =SUMIFS('Counting Class'!V:V,'Counting Class'!J:J,"=1",'Counting Class'!V:V,"=1") -> 0 | E10: =SUMIFS('Counting Class'!W:W,'Counting Class'!K:K,"=1",'Counting Class'!W:W,"=1") -> 7 | F10: =SUMIFS('Counting Class'!X:X,'Counting Class'!L:L,"=1",'Counting Class'!X:X,"=1") -> 0 | G10: =SUMIFS('Counting Class'!Y:Y,'Counting Class'!M:M,"=1",'Counting Class'!Y:Y,"=1") -> 9 | H10: =SUMIFS('Counting Class'!Z:Z,'Counting Class'!N:N,"=1",'Counting Class'!Z:Z,"=1") -> 2 | I10: =SUMIFS('Counting Class'!AA:AA,'Counting Class'!O:O,"=1",'Counting Class'!AA:AA,"=1") -> 0 | J10: =SUMIFS('Counting Class'!AB:AB,'Counting Class'!P:P,"=1",'Counting Class'!AB:AB,"=1") -> 0 | K10: =SUMIFS('Counting Class'!AC:AC,'Counting Class'!Q:Q,"=1",'Counting Class'!AC:AC,"=1") -> 0 | L10: =SUMIFS('Counting Class'!AD:AD,'Counting Class'!R:R,"=1",'Counting Class'!AD:AD,"=1") -> 0 | M10: =SUMIFS('Counting Class'!AE:AE,'Counting Class'!S:S,"=1",'Counting Class'!AE:AE,"=1") -> 0 | N10: =SUMIFS('Counting Class'!AF:AF,'Counting Class'!T:T,"=1",'Counting Class'!AF:AF,"=1") -> 0 | O10: =SUMIFS('Counting Class'!AG:AG,'Counting Class'!U:U,"=1",'Counting Class'!AG:AG,"=1") -> 0 | P10: =SUMIFS('Counting Class'!AH:AH,'Counting Class'!V:V,"=1",'Counting Class'!AH:AH,"=1") -> 0 | R10: =SUM(Areas!$B10:$P10) -> 45
A11: Software Engineering Models and Methods | B11: =SUMIFS('Counting Class'!T:T,'Counting Class'!K:K,"=1",'Counting Class'!T:T,"=1") -> 34 | C11: =SUMIFS('Counting Class'!U:U,'Counting Class'!K:K,"=1",'Counting Class'!U:U,"=1") -> 17 | D11: =SUMIFS('Counting Class'!V:V,'Counting Class'!K:K,"=1",'Counting Class'!V:V,"=1") -> 2 | E11: =SUMIFS('Counting Class'!W:W,'Counting Class'!L:L,"=1",'Counting Class'!W:W,"=1") -> 1 | F11: =SUMIFS('Counting Class'!X:X,'Counting Class'!M:M,"=1",'Counting Class'!X:X,"=1") -> 10 | G11: =SUMIFS('Counting Class'!Y:Y,'Counting Class'!N:N,"=1",'Counting Class'!Y:Y,"=1") -> 0 | H11: =SUMIFS('Counting Class'!Z:Z,'Counting Class'!O:O,"=1",'Counting Class'!Z:Z,"=1") -> 0 | I11: =SUMIFS('Counting Class'!AA:AA,'Counting Class'!P:P,"=1",'Counting Class'!AA:AA,"=1") -> 0 | J11: =SUMIFS('Counting Class'!AB:AB,'Counting Class'!Q:Q,"=1",'Counting Class'!AB:AB,"=1") -> 0 | K11: =SUMIFS('Counting Class'!AC:AC,'Counting Class'!R:R,"=1",'Counting Class'!AC:AC,"=1") -> 0 | L11: =SUMIFS('Counting Class'!AD:AD,'Counting Class'!S:S,"=1",'Counting Class'!AD:AD,"=1") -> 0 | M11: =SUMIFS('Counting Class'!AE:AE,'Counting Class'!T:T,"=1",'Counting Class'!AE:AE,"=1") -> 2 | N11: =SUMIFS('Counting Class'!AF:AF,'Counting Class'!U:U,"=1",'Counting Class'!AF:AF,"=1") -> 0 | O11: =SUMIFS('Counting Class'!AG:AG,'Counting Class'!V:V,"=1",'Counting Class'!AG:AG,"=1") -> 0 | P11: =SUMIFS('Counting Class'!AH:AH,'Counting Class'!W:W,"=1",'Counting Class'!AH:AH,"=1") -> 0 | R11: =SUM(Areas!$B11:$P11) -> 66
A12: Software Engineering Process | B12: =SUMIFS('Counting Class'!T:T,'Counting Class'!L:L,"=1",'Counting Class'!T:T,"=1") -> 3 | C12: =SUMIFS('Counting Class'!U:U,'Counting Class'!L:L,"=1",'Counting Class'!U:U,"=1") -> 5 | D12: =SUMIFS('Counting Class'!V:V,'Counting Class'!L:L,"=1",'Counting Class'!V:V,"=1") -> 0 | E12: =SUMIFS('Counting Class'!W:W,'Counting Class'!M:M,"=1",'Counting Class'!W:W,"=1") -> 11 | F12: =SUMIFS('Counting Class'!X:X,'Counting Class'!N:N,"=1",'Counting Class'!X:X,"=1") -> 2 | G12: =SUMIFS('Counting Class'!Y:Y,'Counting Class'!O:O,"=1",'Counting Class'!Y:Y,"=1") -> 1 | H12: =SUMIFS('Counting Class'!Z:Z,'Counting Class'!P:P,"=1",'Counting Class'!Z:Z,"=1") -> 1 | I12: =SUMIFS('Counting Class'!AA:AA,'Counting Class'!Q:Q,"=1",'Counting Class'!AA:AA,"=1") -> 0 | J12: =SUMIFS('Counting Class'!AB:AB,'Counting Class'!R:R,"=1",'Counting Class'!AB:AB,"=1") -> 0 | K12: =SUMIFS('Counting Class'!AC:AC,'Counting Class'!S:S,"=1",'Counting Class'!AC:AC,"=1") -> 1 | L12: =SUMIFS('Counting Class'!AD:AD,'Counting Class'!T:T,"=1",'Counting Class'!AD:AD,"=1") -> 0 | M12: =SUMIFS('Counting Class'!AE:AE,'Counting Class'!U:U,"=1",'Counting Class'!AE:AE,"=1") -> 2 | N12: =SUMIFS('Counting Class'!AF:AF,'Counting Class'!V:V,"=1",'Counting Class'!AF:AF,"=1") -> 0 | O12: =SUMIFS('Counting Class'!AG:AG,'Counting Class'!W:W,"=1",'Counting Class'!AG:AG,"=1") -> 0 | P12: =SUMIFS('Counting Class'!AH:AH,'Counting Class'!X:X,"=1",'Counting Class'!AH:AH,"=1") -> 0 | R12: =SUM(Areas!$B12:$P12) -> 26
A13: Software Quality | B13: =SUMIFS('Counting Class'!T:T,'Counting Class'!M:M,"=1",'Counting Class'!T:T,"=1") -> 56 | C13: =SUMIFS('Counting Class'!U:U,'Counting Class'!M:M,"=1",'Counting Class'!U:U,"=1") -> 23 | D13: =SUMIFS('Counting Class'!V:V,'Counting Class'!M:M,"=1",'Counting Class'!V:V,"=1") -> 10 | E13: =SUMIFS('Counting Class'!W:W,'Counting Class'!N:N,"=1",'Counting Class'!W:W,"=1") -> 1 | F13: =SUMIFS('Counting Class'!X:X,'Counting Class'!O:O,"=1",'Counting Class'!X:X,"=1") -> 0 | G13: =SUMIFS('Counting Class'!Y:Y,'Counting Class'!P:P,"=1",'Counting Class'!Y:Y,"=1") -> 0 | H13: =SUMIFS('Counting Class'!Z:Z,'Counting Class'!Q:Q,"=1",'Counting Class'!Z:Z,"=1") -> 0 | I13: =SUMIFS('Counting Class'!AA:AA,'Counting Class'!R:R,"=1",'Counting Class'!AA:AA,"=1") -> 0 | J13: =SUMIFS('Counting Class'!AB:AB,'Counting Class'!S:S,"=1",'Counting Class'!AB:AB,"=1") -> 0 | K13: =SUMIFS('Counting Class'!AC:AC,'Counting Class'!T:T,"=1",'Counting Class'!AC:AC,"=1") -> 0 | L13: =SUMIFS('Counting Class'!AD:AD,'Counting Class'!U:U,"=1",'Counting Class'!AD:AD,"=1") -> 0 | M13: =SUMIFS('Counting Class'!AE:AE,'Counting Class'!V:V,"=1",'Counting Class'!AE:AE,"=1") -> 2 | N13: =SUMIFS('Counting Class'!AF:AF,'Counting Class'!W:W,"=1",'Counting Class'!AF:AF,"=1") -> 0 | O13: =SUMIFS('Counting Class'!AG:AG,'Counting Class'!X:X,"=1",'Counting Class'!AG:AG,"=1") -> 0 | P13: =SUMIFS('Counting Class'!AH:AH,'Counting Class'!Y:Y,"=1",'Counting Class'!AH:AH,"=1") -> 0 | R13: =SUM(Areas!$B13:$P13) -> 92
A14: Software Security | B14: =SUMIFS('Counting Class'!T:T,'Counting Class'!N:N,"=1",'Counting Class'!T:T,"=1") -> 10 | C14: =SUMIFS('Counting Class'!U:U,'Counting Class'!N:N,"=1",'Counting Class'!U:U,"=1") -> 6 | D14: =SUMIFS('Counting Class'!V:V,'Counting Class'!N:N,"=1",'Counting Class'!V:V,"=1") -> 0 | E14: =SUMIFS('Counting Class'!W:W,'Counting Class'!O:O,"=1",'Counting Class'!W:W,"=1") -> 0 | F14: =SUMIFS('Counting Class'!X:X,'Counting Class'!P:P,"=1",'Counting Class'!X:X,"=1") -> 1 | G14: =SUMIFS('Counting Class'!Y:Y,'Counting Class'!Q:Q,"=1",'Counting Class'!Y:Y,"=1") -> 2 | H14: =SUMIFS('Counting Class'!Z:Z,'Counting Class'!R:R,"=1",'Counting Class'!Z:Z,"=1") -> 1 | I14: =SUMIFS('Counting Class'!AA:AA,'Counting Class'!S:S,"=1",'Counting Class'!AA:AA,"=1") -> 0 | J14: =SUMIFS('Counting Class'!AB:AB,'Counting Class'!T:T,"=1",'Counting Class'!AB:AB,"=1") -> 0 | K14: =SUMIFS('Counting Class'!AC:AC,'Counting Class'!U:U,"=1",'Counting Class'!AC:AC,"=1") -> 0 | L14: =SUMIFS('Counting Class'!AD:AD,'Counting Class'!V:V,"=1",'Counting Class'!AD:AD,"=1") -> 0 | M14: =SUMIFS('Counting Class'!AE:AE,'Counting Class'!W:W,"=1",'Counting Class'!AE:AE,"=1") -> 2 | N14: =SUMIFS('Counting Class'!AF:AF,'Counting Class'!X:X,"=1",'Counting Class'!AF:AF,"=1") -> 0 | O14: =SUMIFS('Counting Class'!AG:AG,'Counting Class'!Y:Y,"=1",'Counting Class'!AG:AG,"=1") -> 0 | P14: =SUMIFS('Counting Class'!AH:AH,'Counting Class'!Z:Z,"=1",'Counting Class'!AH:AH,"=1") -> 0 | R14: =SUM(Areas!$B14:$P14) -> 22
A15: Software Engineering Economics | B15: =SUMIFS('Counting Class'!T:T,'Counting Class'!O:O,"=1",'Counting Class'!T:T,"=1") -> 0 | C15: =SUMIFS('Counting Class'!U:U,'Counting Class'!O:O,"=1",'Counting Class'!U:U,"=1") -> 0 | D15: =SUMIFS('Counting Class'!V:V,'Counting Class'!O:O,"=1",'Counting Class'!V:V,"=1") -> 0 | E15: =SUMIFS('Counting Class'!W:W,'Counting Class'!P:P,"=1",'Counting Class'!W:W,"=1") -> 0 | F15: =SUMIFS('Counting Class'!X:X,'Counting Class'!Q:Q,"=1",'Counting Class'!X:X,"=1") -> 1 | G15: =SUMIFS('Counting Class'!Y:Y,'Counting Class'!R:R,"=1",'Counting Class'!Y:Y,"=1") -> 1 | H15: =SUMIFS('Counting Class'!Z:Z,'Counting Class'!S:S,"=1",'Counting Class'!Z:Z,"=1") -> 1 | I15: =SUMIFS('Counting Class'!AA:AA,'Counting Class'!T:T,"=1",'Counting Class'!AA:AA,"=1") -> 0 | J15: =SUMIFS('Counting Class'!AB:AB,'Counting Class'!U:U,"=1",'Counting Class'!AB:AB,"=1") -> 0 | K15: =SUMIFS('Counting Class'!AC:AC,'Counting Class'!V:V,"=1",'Counting Class'!AC:AC,"=1") -> 0 | L15: =SUMIFS('Counting Class'!AD:AD,'Counting Class'!W:W,"=1",'Counting Class'!AD:AD,"=1") -> 0 | M15: =SUMIFS('Counting Class'!AE:AE,'Counting Class'!X:X,"=1",'Counting Class'!AE:AE,"=1") -> 0 | N15: =SUMIFS('Counting Class'!AF:AF,'Counting Class'!Y:Y,"=1",'Counting Class'!AF:AF,"=1") -> 0 | O15: =SUMIFS('Counting Class'!AG:AG,'Counting Class'!Z:Z,"=1",'Counting Class'!AG:AG,"=1") -> 0 | P15: =SUMIFS('Counting Class'!AH:AH,'Counting Class'!AA:AA,"=1",'Counting Class'!AH:AH,"=1") -> 0 | R15: =SUM(Areas!$B15:$P15) -> 3
A16: Software Engineering Professional Practice | B16: =SUMIFS('Counting Class'!T:T,'Counting Class'!P:P,"=1",'Counting Class'!T:T,"=1") -> 3 | C16: =SUMIFS('Counting Class'!U:U,'Counting Class'!P:P,"=1",'Counting Class'!U:U,"=1") -> 0 | D16: =SUMIFS('Counting Class'!V:V,'Counting Class'!P:P,"=1",'Counting Class'!V:V,"=1") -> 0 | E16: =SUMIFS('Counting Class'!W:W,'Counting Class'!Q:Q,"=1",'Counting Class'!W:W,"=1") -> 0 | F16: =SUMIFS('Counting Class'!X:X,'Counting Class'!R:R,"=1",'Counting Class'!X:X,"=1") -> 1 | G16: =SUMIFS('Counting Class'!Y:Y,'Counting Class'!S:S,"=1",'Counting Class'!Y:Y,"=1") -> 1 | H16: =SUMIFS('Counting Class'!Z:Z,'Counting Class'!T:T,"=1",'Counting Class'!Z:Z,"=1") -> 4 | I16: =SUMIFS('Counting Class'!AA:AA,'Counting Class'!U:U,"=1",'Counting Class'!AA:AA,"=1") -> 2 | J16: =SUMIFS('Counting Class'!AB:AB,'Counting Class'!V:V,"=1",'Counting Class'!AB:AB,"=1") -> 0 | K16: =SUMIFS('Counting Class'!AC:AC,'Counting Class'!W:W,"=1",'Counting Class'!AC:AC,"=1") -> 0 | L16: =SUMIFS('Counting Class'!AD:AD,'Counting Class'!X:X,"=1",'Counting Class'!AD:AD,"=1") -> 0 | M16: =SUMIFS('Counting Class'!AE:AE,'Counting Class'!Y:Y,"=1",'Counting Class'!AE:AE,"=1") -> 0 | N16: =SUMIFS('Counting Class'!AF:AF,'Counting Class'!Z:Z,"=1",'Counting Class'!AF:AF,"=1") -> 0 | O16: =SUMIFS('Counting Class'!AG:AG,'Counting Class'!AA:AA,"=1",'Counting Class'!AG:AG,"=1") -> 0 | P16: =SUMIFS('Counting Class'!AH:AH,'Counting Class'!AB:AB,"=1",'Counting Class'!AH:AH,"=1") -> 0 | R16: =SUM(Areas!$B16:$P16) -> 11
A17: Computing Foundations | B17: =SUMIFS('Counting Class'!T:T,'Counting Class'!Q:Q,"=1",'Counting Class'!T:T,"=1") -> 11 | C17: =SUMIFS('Counting Class'!U:U,'Counting Class'!Q:Q,"=1",'Counting Class'!U:U,"=1") -> 4 | D17: =SUMIFS('Counting Class'!V:V,'Counting Class'!Q:Q,"=1",'Counting Class'!V:V,"=1") -> 0 | E17: =SUMIFS('Counting Class'!W:W,'Counting Class'!R:R,"=1",'Counting Class'!W:W,"=1") -> 1 | F17: =SUMIFS('Counting Class'!X:X,'Counting Class'!S:S,"=1",'Counting Class'!X:X,"=1") -> 1 | G17: =SUMIFS('Counting Class'!Y:Y,'Counting Class'!T:T,"=1",'Counting Class'!Y:Y,"=1") -> 8 | H17: =SUMIFS('Counting Class'!Z:Z,'Counting Class'!U:U,"=1",'Counting Class'!Z:Z,"=1") -> 5 | I17: =SUMIFS('Counting Class'!AA:AA,'Counting Class'!V:V,"=1",'Counting Class'!AA:AA,"=1") -> 0 | J17: =SUMIFS('Counting Class'!AB:AB,'Counting Class'!W:W,"=1",'Counting Class'!AB:AB,"=1") -> 0 | K17: =SUMIFS('Counting Class'!AC:AC,'Counting Class'!X:X,"=1",'Counting Class'!AC:AC,"=1") -> 0 | L17: =SUMIFS('Counting Class'!AD:AD,'Counting Class'!Y:Y,"=1",'Counting Class'!AD:AD,"=1") -> 0 | M17: =SUMIFS('Counting Class'!AE:AE,'Counting Class'!Z:Z,"=1",'Counting Class'!AE:AE,"=1") -> 0 | N17: =SUMIFS('Counting Class'!AF:AF,'Counting Class'!AA:AA,"=1",'Counting Class'!AF:AF,"=1") -> 0 | O17: =SUMIFS('Counting Class'!AG:AG,'Counting Class'!AB:AB,"=1",'Counting Class'!AG:AG,"=1") -> 0 | P17: =SUMIFS('Counting Class'!AH:AH,'Counting Class'!AC:AC,"=1",'Counting Class'!AH:AH,"=1") -> 0 | R17: =SUM(Areas!$B17:$P17) -> 30
A18: Mathematical Foundations | B18: =SUMIFS('Counting Class'!T:T,'Counting Class'!R:R,"=1",'Counting Class'!T:T,"=1") -> 8 | C18: =SUMIFS('Counting Class'!U:U,'Counting Class'!R:R,"=1",'Counting Class'!U:U,"=1") -> 9 | D18: =SUMIFS('Counting Class'!V:V,'Counting Class'!R:R,"=1",'Counting Class'!V:V,"=1") -> 1 | E18: =SUMIFS('Counting Class'!W:W,'Counting Class'!S:S,"=1",'Counting Class'!W:W,"=1") -> 0 | F18: =SUMIFS('Counting Class'!X:X,'Counting Class'!T:T,"=1",'Counting Class'!X:X,"=1") -> 15 | G18: =SUMIFS('Counting Class'!Y:Y,'Counting Class'!U:U,"=1",'Counting Class'!Y:Y,"=1") -> 6 | H18: =SUMIFS('Counting Class'!Z:Z,'Counting Class'!V:V,"=1",'Counting Class'!Z:Z,"=1") -> 3 | I18: =SUMIFS('Counting Class'!AA:AA,'Counting Class'!W:W,"=1",'Counting Class'!AA:AA,"=1") -> 0 | J18: =SUMIFS('Counting Class'!AB:AB,'Counting Class'!X:X,"=1",'Counting Class'!AB:AB,"=1") -> 0 | K18: =SUMIFS('Counting Class'!AC:AC,'Counting Class'!Y:Y,"=1",'Counting Class'!AC:AC,"=1") -> 0 | L18: =SUMIFS('Counting Class'!AD:AD,'Counting Class'!Z:Z,"=1",'Counting Class'!AD:AD,"=1") -> 0 | M18: =SUMIFS('Counting Class'!AE:AE,'Counting Class'!AA:AA,"=1",'Counting Class'!AE:AE,"=1") -> 0 | N18: =SUMIFS('Counting Class'!AF:AF,'Counting Class'!AB:AB,"=1",'Counting Class'!AF:AF,"=1") -> 0 | O18: =SUMIFS('Counting Class'!AG:AG,'Counting Class'!AC:AC,"=1",'Counting Class'!AG:AG,"=1") -> 0 | P18: =SUMIFS('Counting Class'!AH:AH,'Counting Class'!AD:AD,"=1",'Counting Class'!AH:AH,"=1") -> 0 | R18: =SUM(Areas!$B18:$P18) -> 42
A19: Engineering Foundations | B19: =SUMIFS('Counting Class'!T:T,'Counting Class'!S:S,"=1",'Counting Class'!T:T,"=1") -> 2 | C19: =SUMIFS('Counting Class'!U:U,'Counting Class'!S:S,"=1",'Counting Class'!U:U,"=1") -> 1 | D19: =SUMIFS('Counting Class'!V:V,'Counting Class'!S:S,"=1",'Counting Class'!V:V,"=1") -> 0 | E19: =SUMIFS('Counting Class'!W:W,'Counting Class'!T:T,"=1",'Counting Class'!W:W,"=1") -> 11 | F19: =SUMIFS('Counting Class'!X:X,'Counting Class'!U:U,"=1",'Counting Class'!X:X,"=1") -> 7 | G19: =SUMIFS('Counting Class'!Y:Y,'Counting Class'!V:V,"=1",'Counting Class'!Y:Y,"=1") -> 2 | H19: =SUMIFS('Counting Class'!Z:Z,'Counting Class'!W:W,"=1",'Counting Class'!Z:Z,"=1") -> 2 | I19: =SUMIFS('Counting Class'!AA:AA,'Counting Class'!X:X,"=1",'Counting Class'!AA:AA,"=1") -> 0 | J19: =SUMIFS('Counting Class'!AB:AB,'Counting Class'!Y:Y,"=1",'Counting Class'!AB:AB,"=1") -> 0 | K19: =SUMIFS('Counting Class'!AC:AC,'Counting Class'!Z:Z,"=1",'Counting Class'!AC:AC,"=1") -> 0 | L19: =SUMIFS('Counting Class'!AD:AD,'Counting Class'!AA:AA,"=1",'Counting Class'!AD:AD,"=1") -> 0 | M19: =SUMIFS('Counting Class'!AE:AE,'Counting Class'!AB:AB,"=1",'Counting Class'!AE:AE,"=1") -> 0 | N19: =SUMIFS('Counting Class'!AF:AF,'Counting Class'!AC:AC,"=1",'Counting Class'!AF:AF,"=1") -> 0 | O19: =SUMIFS('Counting Class'!AG:AG,'Counting Class'!AD:AD,"=1",'Counting Class'!AG:AG,"=1") -> 0 | P19: =SUMIFS('Counting Class'!AH:AH,'Counting Class'!AE:AE,"=1",'Counting Class'!AH:AH,"=1") -> 0 | R19: =SUM(Areas!$B19:$P19) -> 25
A21: Sub-Total (bearing in mind that the same paper can be connected with several Knowledge areas) | B21: =SUM(Areas!$B$2:$B$19) -> 265 | C21: =SUM(Areas!$C$2:$C$19) -> 112 | D21: =SUM(Areas!$D$2:$D$19) -> 19 | E21: =SUM(Areas!$E$2:$E$19) -> 35 | F21: =SUM(Areas!$F$2:$F$19) -> 50 | G21: =SUM(Areas!$G$2:$G$19) -> 40 | H21: =SUM(Areas!$H$2:$H$19) -> 32 | I21: =SUM(Areas!$I$2:$I$19) -> 7 | J21: =SUM(Areas!$J$2:$J$19) -> 0 | K21: =SUM(Areas!$K$2:$K$19) -> 14 | L21: =SUM(Areas!$L$2:$L$19) -> 1 | M21: =SUM(Areas!$M$2:$M$19) -> 10 | N21: =SUM(Areas!$N$2:$N$19) -> 1 | O21: =SUM(Areas!$O$2:$O$19) -> 0 | P21: =SUM(Areas!$P$2:$P$19) -> 0
A24: Recorded count for each SWEBOK guide V4 knowledge area | B24: Sub-Total
A25: Software Quality | B25: 92
A26: Software Engineering Models and Methods | B26: 66
A27: Software Architecture | B27: 60
A28: Software Requirements | B28: 50
A29: Software Engineering Management | B29: 45
A30: Mathematical Foundations | B30: 42
A31: Software Testing | B31: 33
A32: Computing Foundations | B32: 30
A33: Software Engineering Process | B33: 26
A34: Engineering Foundations | B34: 25
A35: Software Configuration Management | B35: 24
A36: Software Security | B36: 22
... A42: Software Engineering Economics | B42: 3
A45: Recorded count for each SWEBOK guide V4 knowledge area | B45: AHP | C45: TOPSIS | D45: VIKOR | E45: PROMETHEE | F45: ANP | G45: ELECTRE | H45: DEMATEL | I45: TODIM | J45: MULTIMOORA | K45: MACBETH | L45: DRSA | M45: WPM | N45: CBR | O45: FITRADEOFF | P45: PAPRIKA | R45: Sub-Total
A46: Software Quality | B46: 56 | C46: 23 | D46: 10 | E46: 1 | F46: 0 | G46: 0 | H46: 0 | I46: 0 | J46: 0 | K46: 0 | L46: 0 | M46: 2 | N46: 0 | O46: 0 | P46: 0 | R46: 92
A47: Software Engineering Models and Methods | B47: 34 | C47: 17 | D47: 2 | E47: 1 | F47: 10 | G47: 0 | H47: 0 | I47: 0 | J47: 0 | K47: 0 | L47: 0 | M47: 2 | N47: 0 | O47: 0 | P47: 0 | R47: 66
A48: Software Architecture | B48: 36 | C48: 14 | D48: 4 | E48: 0 | F48: 1 | G48: 2 | H48: 0 | I48: 0 | J48: 0 | K48: 2 | L48: 0 | M48: 0 | N48: 1 | O48: 0 | P48: 0 | R48: 60
A49: Software Requirements | B49: 33 | C49: 10 | D49: 1 | E49: 2 | F49: 2 | G49: 1 | H49: 1 | I49: 0 | J49: 0 | K49: 0 | L49: 0 | M49: 0 | N49: 0 | O49: 0 | P49: 0 | R49: 50
A50: Software Engineering Management | B50: 20 | C50: 7 | D50: 0 | E50: 7 | F50: 0 | G50: 9 | H50: 2 | I50: 0 | J50: 0 | K50: 0 | L50: 0 | M50: 0 | N50: 0 | O50: 0 | P50: 0 | R50: 45
...

Sheet Counting Class
A1: Document Title | B1: Requirements | C1: Architecture | D1: Design | E1: Construction | F1: Testing | G1: Engineering Operations | H1: Maintenance | I1: Configuration Management | J1: Engineering Management | K1: Engineering Models and Methods | L1: Engineering Process | M1: Quality | N1: Security | O1: Engineering Economics | P1: Engineering Professional Practice | Q1: Computing Foundations | R1: Mathematical Foundations | S1: Engineering Foundations | T1: AHP | U1: TOPSIS | V1: VIKOR | W1: PROMETHEE | X1: ANP | Y1: ELECTRE | Z1: DEMATEL | AA1: TODIM | AB1: MULTIMOORA | AC1: MACBETH | AD1: DRSA | AE1: WPM | AF1: CBR | AG1: FITRADEOFF | AH1: PAPRIKA
A2: A comparison of two multi-criteria decision-making techniques | D2: 1 | T2: 1
A3: A Component Selection Framework for COTS Libraries | C3: 1 | T3: 1
A4: A decision analysis approach for selecting software defect prediction method in the early phases | M4: 1 | T4: 1 | U4: 1 | W4: 1 | X4: 1 | Y4: 1
A5: A Framework for Selection of SAAS by Evaluating the Quality of Freemium Model | M5: 1 | T5: 1 | X5: 1
A6: A Framework for Software Quality Model Selection using TOPSIS | H6: 1 | M6: 1 | U6: 1
A7: A Fuzzy AHP and TOPSIS Approach for Web Service Selection | M7: 1 | T7: 1 | U7: 1 | V7: 1 | W7: 1
A8: A Fuzzy AHP Approach to Network Selection Improvement in Heterogeneous Wireless Networks | M8: 1 | T8: 1 | U8: 1
A9: A Fuzzy Decision Support Approach for Model-Based Tradeoff Analysis of Non-Functional Requirements | B9: 1 | C9: 1 | T9: 1 | U9: 1
A10: A Fuzzy Multi Criteria Decision Making Approach to Software Life Cycle Model Selection | C10: 1 | L10: 1 | T10: 1 | U10: 1
A11: A Heuristic Approach to Dynamically Update Approximations of Dominance Based Rough Set Theory | Q11: 1 | AD11: 1
A12: A hybrid approach to automatic IaaS service selection | K12: 1 | T12: 1 | U12: 1 | W12: 1 | X12: 1 | Y12: 1
A13: A Hybrid Fuzzy Outranking Approach for Group Decision-Making under Uncertainty | O13: 1 | Y13: 1
A14: A hybrid multi-criteria decision making algorithm for cloud service selection | C14: 1 | M14: 1 | T14: 1 | U14: 1 | V14: 1 | W14: 1 | AE14: 1
A15: A hybrid technique for evaluating the trust of cloud services | C15: 1 | K15: 1 | R15: 1 | T15: 1 | U15: 1 | V15: 1
A16: A Lightweight Value-based Software Architecture Evaluation | C16: 1 | E16: 1 | T16: 1
A17: A Machine Learning Model Comparison and Selection Framework for Software Defect Prediction Using VIKOR | B17: 1 | F17: 1 | M17: 1 | V17: 1
A18: A mathematical programming approach to quantify structural complexity of a conceptual model | C18: 1 | K18: 1 | M18: 1 | T18: 1
A19: A Model Driven Approach for Personalizing Data Source Selection in Mediation Systems | K19: 1 | M19: 1 | AF19: 1
A20: A Model Proposal for Usability Scoring of Websites | K20: 1 | T20: 1
A21: A multi criteria group decision making approach for collaborative software selection problem | J21: 1 | K21: 1 | L21: 1 | T21: 1 | U21: 1
A22: A multi-attribute decision making approach for on-demand charging scheduling in wireless rechargeable sensor networks | K22: 1 | R22: 1 | T22: 1 | U22: 1
A23: A Multi-Criteria Approach for Assessing Cloud Deployment Options Based on Non-Functional Requirements | B23: 1 | C23: 1 | D23: 1 | E23: 1 | T23: 1
A24: A Multi-criteria Decision Making Framework for Real Time Model-Based Testing | F24: 1 | T24: 1
A25: A Multi-criteria Model Application in the Prioritization of Processes for Automation in the Scenario of Intelligence and Investigation Units | L25: 1 | AC25: 1
A26: A Multi-criteria Model for Planning and Fine-Tuning Distributed Scrum Projects | J26: 1 | L26: 1 | AC26: 1
A27: A novel CRITIC-TOPSIS approach for optimal selection of software reliability growth model (SRGM) | F27: 1 | K27: 1 | U27: 1
A28: A novel fuzzy mechanism for risk assessment in software projects | J28: 1 | L28: 1 | M28: 1 | U28: 1 | Z28: 1 | AA28: 1
A29: A Novel Hybrid MADM Based Competence Set Expansions of a SOC Design Service Firm | D29: 1 | T29: 1 | X29: 1 | Z29: 1
A30: A Novel Software Package Selection Method Using Teaching-Learning Based Optimization and Multiple Criteria Decision Making | B30: 1 | K30: 1 | T30: 1 | U30: 1
A31: A Performance Evaluation Model for Project Management Office Based on a Multicriteria Approach | J31: 1 | M31: 1 | AC31: 1
A32: A Practical Approach for Evaluating and Prioritizing Situational Factors in Global Software Project Development | J32: 1 | K32: 1 | T32: 1
A33: A Proposed Requirements Prioritization Model Based on Cost-Value Approach with Collaboration Perspective | B33: 1 | T33: 1 | U33: 1
A34: A QoS Oriented Broker System for Autonomic Web Services Selection | K34: 1 | M34: 1 | W34: 1
A35: A Quality Performance Model for Cost-Benefit Analysis of Non-functional Requirements Applied to the Mobile Handset Domain | B35: 1 | K35: 1 | M35: 1 | T35: 1
A36: A quality-driven decision-support method for identifying software architecture candidates | B36: 1 | C36: 1 | M36: 1 | T36: 1
A37: A real options approach for software development projects using fuzzy electre | J37: 1 | L37: 1 | Y37: 1
A38: A Roadmap for Migration System-Architecture Decision by Neutrosophic-ANP and Benchmark for Enterprise Resource Planning Systems | C38: 1 | F38: 1 | I38: 1 | T38: 1 | X38: 1
A39: A robust decision-making methodology for evaluation and selection of simulation software package | J39: 1 | T39: 1
A40: A rough-set based approach for the prioritization of software requirements | B40: 1 | T40: 1 | U40: 1
...
